[2023-11-26 16:45:46] [INFO    ] discord.client: logging in using static token
[2023-11-26 16:45:48] [INFO    ] discord.gateway: Shard ID None has connected to Gateway (Session ID: 33fd7232d81fe47fd41ed6c32720931f).
[2023-11-26 16:46:22] [ERROR   ] discord.app_commands.tree: Ignoring exception in command 'schedule'
Traceback (most recent call last):
  File "/home/emil/.local/lib/python3.10/site-packages/discord/app_commands/commands.py", line 828, in _do_call
    return await self._callback(interaction, **params)  # type: ignore
  File "/home/emil/inhouse-buddy/main.py", line 39, in schedule
    await schedule_command(interaction, date, time)
  File "/home/emil/inhouse-buddy/Commands/schedule.py", line 28, in schedule_command
    db_handler.schedule_match(match_datetime.strftime("%Y-%m-%d %H:%M"))
  File "/home/emil/inhouse-buddy/DatabaseHandler.py", line 35, in schedule_match
    self.c.execute("INSERT INTO scheduled_matches VALUES (?)", (datetime_string,))
sqlite3.IntegrityError: UNIQUE constraint failed: scheduled_matches.datetime

The above exception was the direct cause of the following exception:

Traceback (most recent call last):
  File "/home/emil/.local/lib/python3.10/site-packages/discord/app_commands/tree.py", line 1248, in _call
    await command._invoke_with_namespace(interaction, namespace)
  File "/home/emil/.local/lib/python3.10/site-packages/discord/app_commands/commands.py", line 853, in _invoke_with_namespace
    return await self._do_call(interaction, transformed_values)
  File "/home/emil/.local/lib/python3.10/site-packages/discord/app_commands/commands.py", line 846, in _do_call
    raise CommandInvokeError(self, e) from e
discord.app_commands.errors.CommandInvokeError: Command 'schedule' raised an exception: IntegrityError: UNIQUE constraint failed: scheduled_matches.datetime
[2023-11-26 16:50:04] [ERROR   ] discord.app_commands.tree: Ignoring exception in command 'schedule'
Traceback (most recent call last):
  File "/home/emil/.local/lib/python3.10/site-packages/discord/app_commands/commands.py", line 828, in _do_call
    return await self._callback(interaction, **params)  # type: ignore
  File "/home/emil/inhouse-buddy/main.py", line 39, in schedule
    await schedule_command(interaction, date, time)
  File "/home/emil/inhouse-buddy/Commands/schedule.py", line 73, in schedule_command
    await interaction.response.send_message(embed=embed, view=view, delete_after=6000)
  File "/home/emil/.local/lib/python3.10/site-packages/discord/interactions.py", line 801, in send_message
    await adapter.create_interaction_response(
  File "/home/emil/.local/lib/python3.10/site-packages/discord/webhook/async_.py", line 219, in request
    raise NotFound(response, data)
discord.errors.NotFound: 404 Not Found (error code: 10062): Unknown interaction

The above exception was the direct cause of the following exception:

Traceback (most recent call last):
  File "/home/emil/.local/lib/python3.10/site-packages/discord/app_commands/tree.py", line 1248, in _call
    await command._invoke_with_namespace(interaction, namespace)
  File "/home/emil/.local/lib/python3.10/site-packages/discord/app_commands/commands.py", line 853, in _invoke_with_namespace
    return await self._do_call(interaction, transformed_values)
  File "/home/emil/.local/lib/python3.10/site-packages/discord/app_commands/commands.py", line 846, in _do_call
    raise CommandInvokeError(self, e) from e
discord.app_commands.errors.CommandInvokeError: Command 'schedule' raised an exception: NotFound: 404 Not Found (error code: 10062): Unknown interaction
[2023-11-26 16:50:25] [ERROR   ] discord.app_commands.tree: Ignoring exception in command 'schedule'
Traceback (most recent call last):
  File "/home/emil/.local/lib/python3.10/site-packages/discord/app_commands/commands.py", line 828, in _do_call
    return await self._callback(interaction, **params)  # type: ignore
  File "/home/emil/inhouse-buddy/main.py", line 39, in schedule
    await schedule_command(interaction, date, time)
  File "/home/emil/inhouse-buddy/Commands/schedule.py", line 28, in schedule_command
    db_handler.schedule_match(match_datetime.strftime("%Y-%m-%d %H:%M"))
  File "/home/emil/inhouse-buddy/DatabaseHandler.py", line 35, in schedule_match
    self.c.execute("INSERT INTO scheduled_matches VALUES (?)", (datetime_string,))
sqlite3.IntegrityError: UNIQUE constraint failed: scheduled_matches.datetime

The above exception was the direct cause of the following exception:

Traceback (most recent call last):
  File "/home/emil/.local/lib/python3.10/site-packages/discord/app_commands/tree.py", line 1248, in _call
    await command._invoke_with_namespace(interaction, namespace)
  File "/home/emil/.local/lib/python3.10/site-packages/discord/app_commands/commands.py", line 853, in _invoke_with_namespace
    return await self._do_call(interaction, transformed_values)
  File "/home/emil/.local/lib/python3.10/site-packages/discord/app_commands/commands.py", line 846, in _do_call
    raise CommandInvokeError(self, e) from e
discord.app_commands.errors.CommandInvokeError: Command 'schedule' raised an exception: IntegrityError: UNIQUE constraint failed: scheduled_matches.datetime
